Workbook

Sheet BSE DATA AND CORRELATION
A1: BSE HISTORICAL DATA | G1: Years | H1: Budget launch Date | I1: Correlation | J1: Lets find correlation of budget and BSE value
G2: 2010 - 11 | H2: 40235 | I2: 0.90494 | K2: YEAR | L2: Date | P2: Years | Q2: Budget Launch Date | R2: Correlation
A3: Month | B3: Open | C3: High | D3: Low | E3: Close | G3: 2011 - 12 | H3: 40602 | I3: =N15 -> 0.68977 | K3: 2010-11 | L3: 40235 | P3: 2016 - 17 | Q3: 42429 | R3: 0.49021729
A4: 40179 | B4: 17473.45 | C4: 17790.33 | D4: 15982.08 | E4: 16357.96 | G4: 2012 - 13 | H4: 40984 | I4: =N24 -> 0.02305 | P4: 2017 - 18 | Q4: 42767 | R4: 0.9722749
A5: 40210 | B5: 16339.32 | C5: 16669.25 | D5: 15651.99 | E5: 16429.55 | G5: 2013 - 14 | H5: 41333 | I5: =N32 -> -0.30092 | K5: Months | L5: Close | M5: Correlation | N5: Value | P5: 2018 - 19 | Q5: 43132 | R5: -0.35686255
A6: 40238 | B6: 16438.45 | C6: 17793.01 | D6: 16438.45 | E6: 17527.77 | G6: 2014 - 15 | H6: 41830 | I6: =N40 -> 0.94598 | K6: 40179 | L6: 16357.96 | M6: =CORREL(K6:K9,L6:L9) -> 0.9049465229 | N6: =M6 -> 0.9049465229 | P6: 2019 - 20 | Q6: 43651 | R6: -0.29823588
A7: 40269 | B7: 17555.04 | C7: 18047.86 | D7: 17276.8 | E7: 17558.71 | G7: 2015 - 16 | H7: 42063 | I7: =N48 -> -0.92060 | K7: 40210 | L7: 16429.55 | P7: 2020 - 21 | Q7: 43862 | R7: -0.76566515
A8: 40299 | B8: 17536.86 | C8: 17536.86 | D8: 15960.15 | E8: 16944.63 | G8: 2016 - 17 | H8: 42429 | I8: =N56 -> 0.49022 | K8: 40238 | L8: 17527.77 | P8: 2021 - 22 | Q8: 44228 | R8: 0.70388043
A9: 40330 | B9: 16942.82 | C9: 17919.62 | D9: 16318.39 | E9: 17700.9 | G9: 2017 - 18 | H9: 42767 | I9: =N64 -> 0.97227 | K9: 40269 | L9: 17558.71 | P9: 2022 - 23 | Q9: 44593 | R9: -0.087719001
A10: 40360 | B10: 17679.34 | C10: 18237.56 | D10: 17395.58 | E10: 17868.29 | G10: 2018 - 19 | H10: 43132 | I10: =N72 -> -0.35686 | P10: 2023 - 24 | Q10: 44958 | R10: 0.60708679
A11: 40391 | B11: 17911.31 | C11: 18475.27 | D11: 17819.99 | E11: 17971.12 | G11: 2019 - 20 | H11: 43651 | I11: =N80 -> -0.29824 | R11: =AVERAGE('BSE DATA AND CORRELATION'!$R$3:$R$10) -> 0.15812
A12: 40422 | B12: 18027.12 | C12: 20267.98 | D12: 18027.12 | E12: 20069.12 | G12: 2020 - 21 | H12: 43862 | I12: =N88 -> -0.76567 | K12: 2011-12 | L12: 40602
A13: 40452 | B13: 20094.1 | C13: 20854.55 | D13: 19768.96 | E13: 20032.34 | G13: 2021 - 22 | H13: 44228 | I13: =N96 -> 0.70388
A14: 40483 | B14: 20272.49 | C14: 21108.64 | D14: 18954.82 | E14: 19521.25 | G14: 2022 - 23 | H14: 44593 | I14: =N104 -> -0.08772 | K14: Months | L14: Close | M14: Correlation | N14: Value
A15: 40513 | B15: 19529.99 | C15: 20552.03 | D15: 19074.57 | E15: 20509.09 | G15: 2023 - 24 | H15: 44958 | I15: =M112 -> 0.60709 | K15: 40544 | L15: 18327.76 | M15: =CORREL(K15:K18,L15:L18) -> 0.6897678407 | N15: =M15 -> 0.6897678407
A16: 40544 | B16: 20621.61 | C16: 20664.8 | D16: 18038.48 | E16: 18327.76 | I16: =SUBTOTAL(104,'BSE DATA AND CORRELATION'!$I$2:$I$15) -> 0.97227 | K16: 40575 | L16: 17823.4
A17: 40575 | B17: 18425.18 | C17: 18690.97 | D17: 17295.62 | E17: 17823.4 | K17: 40603 | L17: 19445.22
A18: 40603 | B18: 17982.28 | C18: 19575.16 | D18: 17792.17 | E18: 19445.22 | G18: YEAR | H18: Date | K18: 40634 | L18: 19135.96
A19: 40634 | B19: 19463.11 | C19: 19811.14 | D19: 18976.19 | E19: 19135.96
A20: 40664 | B20: 19224.05 | C20: 19253.87 | D20: 17786.13 | E20: 18503.28
A21: 40695 | B21: 18527.12 | C21: 18873.39 | D21: 17314.38 | E21: 18845.87 | G21: Months | H21: Close | I21: Correlation | K21: 2012-13 | L21: 40984
A22: 40725 | B22: 18974.96 | C22: 19131.7 | D22: 18131.86 | E22: 18197.2 | I22: =CORREL(G22:G25,H22:H25) -> #DIV/0!
A23: 40756 | B23: 18352.23 | C23: 18440.07 | D23: 15765.53 | E23: 16676.75 | K23: Months | L23: Close | M23: Correlation | N23: Value
A24: 40787 | B24: 16963.67 | C24: 17211.8 | D24: 15801.01 | E24: 16453.76 | K24: 40909 | L24: 17193.55 | M24: =CORREL(K24:K27,L24:L27) -> 0.02304956611 | N24: =M24 -> 0.02304956611
A25: 40817 | B25: 16255.97 | C25: 17908.13 | D25: 15745.43 | E25: 17705.01 | K25: 40940 | L25: 17752.68
A26: 40848 | B26: 17540.55 | C26: 17702.26 | D26: 15478.69 | E26: 16123.46 | K26: 40969 | L26: 17404.2
A27: 40878 | B27: 16555.93 | C27: 17003.71 | D27: 15135.86 | E27: 15454.92 | K27: 41000 | L27: 17318.81
A28: 40909 | B28: 15534.67 | C28: 17258.97 | D28: 15358.02 | E28: 17193.55
A29: 40940 | B29: 17179.64 | C29: 18523.78 | D29: 17061.55 | E29: 17752.68 | K29: 2013-14 | L29: 41333
A30: 40969 | B30: 17714.62 | C30: 18040.69 | D30: 16920.61 | E30: 17404.2
A31: 41000 | B31: 17429.96 | C31: 17664.1 | D31: 17010.16 | E31: 17318.81 | K31: Months | L31: Close | M31: Correlation | N31: Value
A32: 41030 | B32: 17370.93 | C32: 17432.33 | D32: 15809.71 | E32: 16218.53 | K32: 41275 | L32: 19894.98 | M32: =CORREL(K32:K35,L32:L35) -> -0.3009151008 | N32: =M32 -> -0.3009151008
A33: 41061 | B33: 16217.48 | C33: 17448.48 | D33: 15748.98 | E33: 17429.98 | K33: 41306 | L33: 18861.54
A34: 41091 | B34: 17438.68 | C34: 17631.19 | D34: 16598.48 | E34: 17236.18 | K34: 41334 | L34: 18835.77
A35: 41122 | B35: 17244.44 | C35: 17972.54 | D35: 17026.97 | E35: 17429.56 | K35: 41365 | L35: 19504.18
A36: 41153 | B36: 17465.6 | C36: 18869.94 | D36: 17250.8 | E36: 18762.74
A37: 41183 | B37: 18784.64 | C37: 19137.29 | D37: 18393.42 | E37: 18505.38 | K37: 2014-15 | L37: 41830
A38: 41214 | B38: 18487.9 | C38: 19372.7 | D38: 18255.69 | E38: 19339.9
A39: 41244 | B39: 19342.83 | C39: 19612.18 | D39: 19149.03 | E39: 19426.71 | K39: Months | L39: Close | M39: Correlation | N39: Value
A40: 41275 | B40: 19513.45 | C40: 20203.66 | D40: 19508.93 | E40: 19894.98 | K40: 41791 | L40: 25413.78 | M40: =CORREL(K40:K43,L40:L43) -> 0.9459821724 | N40: =M40 -> 0.9459821724
...

Sheet BSE CORRELATION WITH PIVOTTABLE
B1: (All) | D1: Years | E1: Budget launch Date | F1: Correlation | H1: Lets find correlation of budget and BSE value
D2: 2010 - 11 | E2: 40235 | F2: 0.90494 | I2: YEAR | J2: Date | N2: 2014-15 | O2: 41830 | S2: 2018-19 | T2: 43132
D3: 2011 - 12 | E3: 40602 | F3: 0.68976784 | I3: 2010-11 | J3: 40235
A4: #REF! | D4: 2012 - 13 | E4: 40984 | F4: 0.023049566 | N4: Months | O4: Close | P4: Correlation | Q4: Value | S4: Months | T4: Close | U4: Correlation | V4: Value
D5: 2013 - 14 | E5: 41333 | F5: -0.3009151 | I5: Months | J5: Close | K5: Correlation | L5: Value | N5: 41791 | O5: 25413.78 | P5: =CORREL(N5:N8,O5:O8) -> 0.9459821724 | Q5: =P5 -> 0.9459821724 | S5: 43101 | T5: 35965.02 | U5: =CORREL(S5:S8,T5:T8) -> -0.3568625467 | V5: =U5 -> -0.3568625467
D6: 2014 - 15 | E6: 41830 | F6: 0.94598217 | I6: 40179 | J6: 16357.96 | K6: =CORREL(I6:I9,J6:J9) -> 0.9049465229 | L6: =K6 -> 0.9049465229 | N6: 41821 | O6: 25894.97 | S6: 43132 | T6: 34184.04
D7: 2015 - 16 | E7: 42063 | F7: -0.92059962 | I7: 40210 | J7: 16429.55 | N7: 41852 | O7: 26638.11 | S7: 43160 | T7: 32968.68
D8: 2016 - 17 | E8: 42429 | F8: 0.49021729 | I8: 40238 | J8: 17527.77 | N8: 41883 | O8: 26630.51 | S8: 43191 | T8: 35160.36
D9: 2017 - 18 | E9: 42767 | F9: 0.9722749 | I9: 40269 | J9: 17558.71
D10: 2018 - 19 | E10: 43132 | F10: -0.35686255 | N10: 2015-16 | O10: 42063 | S10: 2019-20 | T10: 43651
D11: 2019 - 20 | E11: 43651 | F11: -0.29823588
D12: 2020 - 21 | E12: 43862 | F12: -0.76566515 | I12: 2011-12 | J12: 40602 | N12: Months | O12: Close | P12: Correlation | Q12: Value | S12: Months | T12: Close | U12: Correlation | V12: Value
D13: 2021 - 22 | E13: 44228 | F13: 0.70388043 | N13: 42005 | O13: 29182.95 | P13: =CORREL(N13:N16,O13:O16) -> -0.9205996232 | Q13: =P13 -> -0.9205996232 | S13: 43617 | T13: 39394.64 | U13: =CORREL(S13:S16,T13:T16) -> -0.298235875 | V13: =U13 -> -0.298235875
D14: 2022 - 23 | E14: 44593 | F14: -0.087719001 | I14: Months | J14: Close | K14: Correlation | L14: Value | N14: 42036 | O14: 29361.5 | S14: 43647 | T14: 37481.12
F15: =AVERAGE(F2:F14) -> 0.15385 | I15: 40544 | J15: 18327.76 | K15: =CORREL(I15:I18,J15:J18) -> 0.6897678407 | L15: =K15 -> 0.6897678407 | N15: 42064 | O15: 27957.49 | S15: 43678 | T15: 37332.79
I16: 40575 | J16: 17823.4 | N16: 42095 | O16: 27011.31 | S16: 43709 | T16: 38667.33
D17: YEAR | E17: Date | I17: 40603 | J17: 19445.22
I18: 40634 | J18: 19135.96 | N18: 2016-17 | O18: 42429 | S18: 2020-21 | T18: 43862
D20: Months | E20: Close | F20: Correlation | N20: Months | O20: Close | P20: Correlation | Q20: Value | S20: Months | T20: Close | U20: Correlation | V20: Value
F21: =CORREL(D21:D24,E21:E24) -> #DIV/0! | I21: 2012-13 | J21: 40984 | N21: 42370 | O21: 24870.69 | P21: =CORREL(N21:N24,O21:O24) -> 0.4902172871 | Q21: =P21 -> 0.4902172871 | S21: 43831 | T21: 40723.49 | U21: =CORREL(S21:S24,T21:T24) -> -0.7656651501 | V21: =U21 -> -0.7656651501
N22: 42401 | O22: 23002 | S22: 43862 | T22: 38297.29
I23: Months | J23: Close | K23: Correlation | L23: Value | N23: 42430 | O23: 25341.86 | S23: 43891 | T23: 29468.49
I24: 40909 | J24: 17193.55 | K24: =CORREL(I24:I27,J24:J27) -> 0.02304956611 | L24: =K24 -> 0.02304956611 | N24: 42461 | O24: 25606.62 | S24: 43922 | T24: 33717.62
I25: 40940 | J25: 17752.68
I26: 40969 | J26: 17404.2 | N26: 2017-18 | O26: 42767 | S26: 2021-22 | T26: 44228
I27: 41000 | J27: 17318.81
N28: Months | O28: Close | P28: Correlation | Q28: Value | S28: Months | T28: Close | U28: Correlation | V28: Value
I29: 2013-14 | J29: 41333 | N29: 42736 | O29: 27655.96 | P29: =CORREL(N29:N32,O29:O32) -> 0.972274901 | Q29: =P29 -> 0.972274901 | S29: 44197 | T29: 46285.77 | U29: =CORREL(S29:S32,T29:T32) -> 0.7038804279 | V29: =U29 -> 0.7038804279
N30: 42767 | O30: 28743.32 | S30: 44228 | T30: 49099.99
I31: Months | J31: Close | K31: Correlation | L31: Value | N31: 42795 | O31: 29620.5 | S31: 44256 | T31: 49509.15
I32: 41275 | J32: 19894.98 | K32: =CORREL(I32:I35,J32:J35) -> -0.3009151008 | L32: =K32 -> -0.3009151008 | N32: 42826 | O32: 29918.4 | S32: 44287 | T32: 48782.36
I33: 41306 | J33: 18861.54
I34: 41334 | J34: 18835.77 | S34: 2022-23 | T34: 44593
I35: 41365 | J35: 19504.18
S36: Months | T36: Close | U36: Correlation | V36: Value
S37: 44562 | T37: 58014.17 | U37: =CORREL(S37:S40,T37:T40) -> -0.08771900106 | V37: =U37 -> -0.08771900106
S38: 44593 | T38: 56247.28
S39: 44621 | T39: 58568.51
S40: 44652 | T40: 57060.87

Sheet NSE DATA
A1: NSE HISTORICAL INDEX DATA (09-11-15 to 09-04-2024)
J2: Years | K2: Budget launch Date | N2: YEAR | O2: Date
A3: Date | B3: Open | C3: High | D3: Low | E3: Close | F3: Shares Traded | G3: Turnover (â‚¹ Cr) | J3: 2010 - 11 | K3: 40235 | N3: 2016 - 17 | O3: 42429
A4: 42317 | B4: 7788.25 | C4: 7937.75 | D4: 7771.7 | E4: 7915.2 | F4: 218422388 | G4: 9376.17 | J4: 2011 - 12 | K4: 40602
A5: 42318 | B5: 7877.6 | C5: 7885.1 | D5: 7772.85 | E5: 7783.35 | F5: 170267413 | G5: 7153.47 | J5: 2012 - 13 | K5: 40984 | N5: Dates | O5: Close | P5: Correlation
A6: 42319 | B6: 7838.8 | C6: 7847.95 | D6: 7819.1 | E6: 7825 | F6: 22380435 | G6: 1123.44 | J6: 2013 - 14 | K6: 41333 | N6: 42370 | O6: 7963.2 | P6: =CORREL(N6:N9,O6:O9) -> -0.4470991323
A7: 42321 | B7: 7762.45 | C7: 7775.1 | D7: 7730.9 | E7: 7762.25 | F7: 165876819 | G7: 7731.55 | J7: 2014 - 15 | K7: 41830 | N7: 42401 | O7: 7555.95
A8: 42324 | B8: 7732.95 | C8: 7838.85 | D8: 7714.15 | E8: 7806.6 | F8: 154134885 | G8: 6871.15 | J8: 2015 - 16 | K8: 42063 | N8: 42430 | O8: 7222.3
A9: 42325 | B9: 7848.75 | C9: 7860.45 | D9: 7793 | E9: 7837.55 | F9: 149451211 | G9: 6367.14 | J9: 2016 - 17 | K9: 42429 | N9: 42461 | O9: 7713.05
A10: 42326 | B10: 7823.15 | C10: 7843.4 | D10: 7725.05 | E10: 7731.8 | F10: 148037721 | G10: 6112.32 | J10: 2017 - 18 | K10: 42767
A11: 42327 | B11: 7788.5 | C11: 7854.9 | D11: 7765.45 | E11: 7842.75 | F11: 136702518 | G11: 7410.15 | J11: 2018 - 19 | K11: 43132
A12: 42328 | B12: 7841.9 | C12: 7906.95 | D12: 7817.8 | E12: 7856.55 | F12: 156610433 | G12: 7298.01 | J12: 2019 - 20 | K12: 43651 | N12: 2017 - 18 | O12: 42767
A13: 42331 | B13: 7869.5 | C13: 7877.5 | D13: 7825.2 | E13: 7849.25 | F13: 130871603 | G13: 6099.09 | J13: 2020 - 21 | K13: 43862
A14: 42332 | B14: 7837 | C14: 7870.35 | D14: 7812.65 | E14: 7831.6 | F14: 134562905 | G14: 6686.27 | J14: 2021 - 22 | K14: 44228 | N14: Dates | O14: Close | P14: Correlation
A15: 42334 | B15: 7837.15 | C15: 7897.1 | D15: 7832 | E15: 7883.8 | F15: 226632193 | G15: 11054.04 | J15: 2022 - 23 | K15: 44593 | N15: 42737 | O15: 8179.5 | P15: =CORREL(N15:N18,O15:O18) -> 0.9801297604
A16: 42335 | B16: 7910.6 | C16: 7959.3 | D16: 7879.45 | E16: 7942.7 | F16: 154863047 | G16: 7068.72 | J16: 2023 - 24 | K16: 44958 | N16: 42767 | O16: 8716.4
A17: 42338 | B17: 7936.25 | C17: 7966 | D17: 7922.8 | E17: 7935.25 | F17: 223041699 | G17: 15368.67 | N17: 42795 | O17: 8945.8
A18: 42339 | B18: 7958.15 | C18: 7972.15 | D18: 7934.15 | E18: 7954.9 | F18: 142945421 | G18: 6796.67 | N18: 42828 | O18: 9237.85
A19: 42340 | B19: 7976.7 | C19: 7979.3 | D19: 7910.8 | E19: 7931.35 | F19: 130207404 | G19: 6242.53
A20: 42341 | B20: 7902.3 | C20: 7912.3 | D20: 7853.3 | E20: 7864.15 | F20: 129628400 | G20: 5636.41
A21: 42342 | B21: 7817.6 | C21: 7821.4 | D21: 7775.7 | E21: 7781.9 | F21: 157231681 | G21: 7758.36
A22: 42345 | B22: 7816.55 | C22: 7825.4 | D22: 7746.05 | E22: 7765.4 | F22: 141893279 | G22: 6403.97
A23: 42346 | B23: 7738.5 | C23: 7771.25 | D23: 7685.45 | E23: 7701.7 | F23: 139318392 | G23: 5986.06
A24: 42347 | B24: 7695.5 | C24: 7702.85 | D24: 7606.9 | E24: 7612.5 | F24: 144315690 | G24: 6599.6
A25: 42348 | B25: 7643.3 | C25: 7691.95 | D25: 7610 | E25: 7683.3 | F25: 145249292 | G25: 6492.02
A26: 42349 | B26: 7699.6 | C26: 7703.05 | D26: 7575.3 | E26: 7610.45 | F26: 172996480 | G26: 6894.44
A27: 42352 | B27: 7558.2 | C27: 7663.95 | D27: 7551.05 | E27: 7650.05 | F27: 153492615 | G27: 6290.42
A28: 42353 | B28: 7659.15 | C28: 7705 | D28: 7625.1 | E28: 7700.9 | F28: 138479057 | G28: 6152.14
A29: 42354 | B29: 7725.25 | C29: 7776.6 | D29: 7715.75 | E29: 7750.9 | F29: 159149338 | G29: 6703.76
A30: 42355 | B30: 7783.05 | C30: 7852.9 | D30: 7737.55 | E30: 7844.35 | F30: 181256780 | G30: 7367.15
... A594: 43187 | B594: 10143.6 | C594: 10158.35 | D594: 10096.9 | E594: 10113.7 | F594: 354977198 | G594: 18807.48
A595: 43192 | B595: 10151.65 | C595: 10220.1 | D595: 10127.75 | E595: 10211.8
A596: 43193 | B596: 10186.85 | C596: 10255.35 | D596: 10171.05 | E596: 10245 | F596: 211652029 | G596: 10167.12
A597: 43194 | B597: 10274.6 | C597: 10279.85 | D597: 10111.3 | E597: 10128.4 | F597: 238182921 | G597: 11861.79
A598: 43195 | B598: 10228.45 | C598: 10331.8 | D598: 10227.45 | E598: 10325.15 | F598: 244116235 | G598: 11674.92
A599: 43196 | B599: 10322.75 | C599: 10350.45 | D599: 10290.85 | E599: 10331.6 | F599: 206355691 | G599: 10131.74
A600: 43199 | B600: 10333.7 | C600: 10397.7 | D600: 10328.5 | E600: 10379.35 | F600: 228512954 | G600: 10714.13
A601: 43200 | B601: 10412.9 | C601: 10424.85 | D601: 10381.5 | E601: 10402.25 | F601: 259523888 | G601: 11905.12
A602: 43201 | B602: 10428.15 | C602: 10428.15 | D602: 10355.6 | E602: 10417.15 | F602: 258077363 | G602: 11790.58
A603: 43202 | B603: 10410.65 | C603: 10469.9 | D603: 10395.25 | E603: 10458.65 | F603: 246027888 | G603: 12249.66
...

Sheet NSE CORRELATION WITH PIVOTTABLE
B1: 45019
D3: Years | E3: Budget launch Date | F3: Correlation | H3: YEAR | I3: Date
A4: #REF! | D4: 2016 - 17 | E4: 42429 | F4: =K7 -> -0.4470991323 | H4: 2016 - 17 | I4: 42429 | M4: 2019 - 20 | N4: 43651 | R4: 2022 - 23 | S4: 44593
D5: 2017 - 18 | E5: 42767 | F5: =K16 -> 0.9801297604
D6: 2018 - 19 | E6: 43132 | F6: =K25 -> -0.4555769033 | H6: Dates | I6: Close | J6: Correlation | K6: Value | M6: Dates | N6: Close | O6: Correlation | P6: Value | R6: Dates | S6: Close | T6: Correlation | U6: Value
D7: 2019 - 20 | E7: 43651 | F7: =P7 -> 0.7483420712 | H7: 42370 | I7: 7963.2 | J7: =CORREL(H7:H10,I7:I10) -> -0.4470991323 | K7: =J7 -> -0.4470991323 | M7: 43466 | N7: 10910.1 | O7: =CORREL(M7:M10,N7:N10) -> 0.7483420712 | P7: =O7 -> 0.7483420712 | R7: 44564 | S7: 17625.7 | T7: =CORREL(R7:R10,S7:S10) -> -0.2041648325 | U7: =T7 -> -0.2041648325
D8: 2020 - 21 | E8: 43862 | F8: =P16 -> -0.9032207934 | H8: 42401 | I8: 7555.95 | M8: 43497 | N8: 10893.65 | R8: 44593 | S8: 17576.85
D9: 2021 - 22 | E9: 44228 | F9: =P25 -> 0.9710676764 | H9: 42430 | I9: 7222.3 | M9: 43525 | N9: 10863.5 | R9: 44622 | S9: 16605.95
D10: 2022 - 23 | E10: 44593 | F10: =U7 -> -0.2041648325 | H10: 42461 | I10: 7713.05 | M10: 43556 | N10: 11669.15 | R10: 44652 | S10: 17670.45
D11: 2023 - 24 | E11: 44958 | F11: =T16 -> -0.8957642432
E12: =SUBTOTAL(103,'NSE CORRELATION WITH PIVOTTABLE'!$E$4:$E$11) -> 8 | F12: =SUBTOTAL(101,'NSE CORRELATION WITH PIVOTTABLE'!$F$4:$F$11) -> -0.02578579959
H13: 2017 - 18 | I13: 42767 | M13: 2020 - 21 | N13: 43862 | R13: 2023 - 24 | S13: 44958
H15: Dates | I15: Close | J15: Correlation | K15: Value | M15: Dates | N15: Close | O15: Correlation | P15: Value | R15: Dates | S15: Close | T15: Correlation | U15: Value
H16: 42737 | I16: 8179.5 | J16: =CORREL(H16:H19,I16:I19) -> 0.9801297604 | K16: =J16 -> 0.9801297604 | M16: 43831 | N16: 12182.5 | O16: =CORREL(M16:M19,N16:N19) -> -0.9032207934 | P16: =O16 -> -0.9032207934 | R16: 44928 | S16: 18197.45 | T16: =CORREL(R16:R19,S16:S19) -> -0.8957642432 | U16: =T16 -> -0.8957642432
H17: 42767 | I17: 8716.4 | M17: 43862 | N17: 11661.85 | R17: 44958 | S17: 17616.3
H18: 42795 | I18: 8945.8 | M18: 43892 | N18: 11132.75 | R18: 44986 | S18: 17450.9
H19: 42828 | I19: 9237.85 | M19: 43922 | N19: 8253.8 | R19: 45019 | S19: 17398.05
D22: Dates | E22: Close | F22: Correlation | H22: 2018 - 19 | I22: 42767 | M22: 2021 - 22 | N22: 44228
F23: =CORREL(D23:D26,E23:E26) -> #DIV/0!
H24: Dates | I24: Close | J24: Correlation | K24: Value | M24: Dates | N24: Close | O24: Correlation | P24: Value
H25: 43101 | I25: 10435.55 | J25: =CORREL(H25:H28,I25:I28) -> -0.4555769033 | K25: =J25 -> -0.4555769033 | M25: 44197 | N25: 14018.5 | O25: =CORREL(M25:M28,N25:N28) -> 0.9710676764 | P25: =O25 -> 0.9710676764
H26: 43132 | I26: 11016.9 | M26: 44228 | N26: 14281.2
H27: 43160 | I27: 10458.35 | M27: 44256 | N27: 14761.55
H28: 43192 | I28: 10211.8 | M28: 44287 | N28: 14867.35

Sheet NSE MONEYCONTROL DATA
A1: Date | B1: Open | C1: High | D1: Low | E1: Close | G1: Years | H1: Budget launch Date
A2: 45383 | B2: 22455 | C2: 22768.4 | D2: 22303.8 | E2: 22642.75 | G2: 2010 - 11 | H2: 40235 | J2: YEAR | K2: Date
A3: 45352 | B3: 22048.3 | C3: 22526.6 | D3: 21710.2 | E3: 22326.9 | G3: 2011 - 12 | H3: 40602 | J3: 2010 - 11 | K3: 40235
A4: 45323 | B4: 21780.65 | C4: 22297.5 | D4: 21530.2 | E4: 21982.8 | G4: 2012 - 13 | H4: 40984
A5: 45292 | B5: 21727.75 | C5: 22124.15 | D5: 21137.2 | E5: 21725.7 | G5: 2013 - 14 | H5: 41333 | J5: Months | K5: Close | L5: Correlation
A6: 45261 | B6: 20194.1 | C6: 21801.45 | D6: 20183.7 | E6: 21731.4 | G6: 2014 - 15 | H6: 41830 | J6: Jab-24 | L6: =CORREL(J6:J9,K6:K9) -> #DIV/0!
A7: 45231 | B7: 19064.05 | C7: 20158.7 | D7: 18973.7 | E7: 20133.15 | G7: 2015 - 16 | H7: 42063 | J7: 45323
A8: 45200 | B8: 19622.4 | C8: 19849.75 | D8: 18837.85 | E8: 19079.6 | G8: 2016 - 17 | H8: 42429 | J8: 45352
A9: 45170 | B9: 19258.15 | C9: 20222.45 | D9: 19255.7 | E9: 19638.3 | G9: 2017 - 18 | H9: 42767 | J9: 45383
A10: 45139 | B10: 19784 | C10: 19795.6 | D10: 19223.65 | E10: 19253.8 | G10: 2018 - 19 | H10: 43132
A11: 45108 | B11: 19246.5 | C11: 19991.85 | D11: 19234.4 | E11: 19753.8 | G11: 2019 - 20 | H11: 43651
A12: 45078 | B12: 18579.4 | C12: 19201.7 | D12: 18464.55 | E12: 19189.05 | G12: 2020 - 21 | H12: 43862
A13: 45047 | B13: 18124.8 | C13: 18662.45 | D13: 18042.4 | E13: 18534.4 | G13: 2021 - 22 | H13: 44228
A14: 45017 | B14: 17427.95 | C14: 18089.15 | D14: 17312.75 | E14: 18065 | G14: 2022 - 23 | H14: 44593
A15: 44986 | B15: 17360.1 | C15: 17799.95 | D15: 16828.35 | E15: 17359.75 | G15: 2023 - 24 | H15: 44958
A16: 44958 | B16: 17811.6 | C16: 18134.75 | D16: 17255.2 | E16: 17303.95
A17: 44927 | B17: 18131.7 | C17: 18251.95 | D17: 17405.55 | E17: 17662.15
A18: 44896 | B18: 18871.95 | C18: 18887.6 | D18: 17774.25 | E18: 18105.3
A19: 44866 | B19: 18130.7 | C19: 18816.05 | D19: 17959.2 | E19: 18758.35
A20: 44835 | B20: 17102.1 | C20: 18022.8 | D20: 16855.55 | E20: 18012.2
A21: 44805 | B21: 17485.7 | C21: 18096.15 | D21: 16747.7 | E21: 17094.35
A22: 44774 | B22: 17243.2 | C22: 17992.2 | D22: 17154.8 | E22: 17759.3
A23: 44743 | B23: 15703.7 | C23: 17172.8 | D23: 15511.05 | E23: 17158.25
A24: 44713 | B24: 16594.4 | C24: 16793.85 | D24: 15183.4 | E24: 15780.25
A25: 44682 | B25: 16924.45 | C25: 17132.85 | D25: 15735.75 | E25: 16584.55
A26: 44652 | B26: 17436.9 | C26: 18114.65 | D26: 16824.7 | E26: 17102.55
A27: 44621 | B27: 16593.1 | C27: 17559.8 | D27: 15671.45 | E27: 17464.75
... A173: 40179 | B173: 5200.9 | C173: 5310.85 | D173: 4766 | E173: 4882.05

Sheet NSE MONEYCONTROL CORRELATION
B1: 44652 | C1: NSE CORRELATION WITH BUDGET LAUNCH | G1: YEAR | H1: Date | K1: YEAR | L1: Date | O1: YEAR | P1: Date
C2: Years | D2: Budget launch Date | E2: Correlation | G2: 2010 - 11 | H2: 40235 | K2: 2014 - 15 | L2: 41830 | O2: 2018 - 19 | P2: 43132
C3: 2010 - 11 | D3: 40235 | E3: =CORREL('NSE MONEYCONTROL CORRELATION'!$G$5:$G$8,'NSE MONEYCONTROL CORRELATION'!$H$5:$H$8) -> 0.4164665809
A4: #REF! | C4: 2011 - 12 | D4: 40602 | E4: =CORREL('NSE MONEYCONTROL CORRELATION'!$G$14:$G$17,'NSE MONEYCONTROL CORRELATION'!$H$14:$H$17) -> -0.24690135 | G4: Months | H4: Close | I4: Correlation | K4: Months | L4: Close | M4: Correlation | O4: Months | P4: Close | Q4: Correlation
C5: 2012 - 13 | D5: 40984 | E5: =CORREL('NSE MONEYCONTROL CORRELATION'!$G$23:$G$26,'NSE MONEYCONTROL CORRELATION'!$H$23:$H$26) -> -0.9977377244 | G5: 40179 | H5: 5310.85 | I5: =CORREL('NSE MONEYCONTROL CORRELATION'!$G$5:$G$8,'NSE MONEYCONTROL CORRELATION'!$H$5:$H$8) -> 0.4164665809 | K5: 41791 | L5: 7700.05 | M5: =CORREL('NSE MONEYCONTROL CORRELATION'!$K$5:$K$8,'NSE MONEYCONTROL CORRELATION'!$L$5:$L$8) -> 0.9934748741 | O5: 43101 | P5: 11171.55 | Q5: =CORREL('NSE MONEYCONTROL CORRELATION'!$O$5:$O$8,'NSE MONEYCONTROL CORRELATION'!$P$5:$P$8) -> -0.7600860611
C6: 2013 - 14 | D6: 41333 | E6: =CORREL('NSE MONEYCONTROL CORRELATION'!$G$32:$G$35,'NSE MONEYCONTROL CORRELATION'!$H$32:$H$35) -> -0.9599023064 | G6: 40210 | H6: 4992 | K6: 41821 | L6: 7840.95 | O6: 43132 | P6: 11117.35
C7: 2014 - 15 | D7: 41830 | E7: =CORREL('NSE MONEYCONTROL CORRELATION'!$K$5:$K$8,'NSE MONEYCONTROL CORRELATION'!$L$5:$L$8) -> 0.9934748741 | G7: 40238 | H7: 5329.55 | K7: 41852 | L7: 7968.25 | O7: 43160 | P7: 10525.5
C8: 2015 - 16 | D8: 42063 | E8: =CORREL('NSE MONEYCONTROL CORRELATION'!$K$14:$K$17,'NSE MONEYCONTROL CORRELATION'!$L$14:$L$17) -> -0.3280414061 | G8: 40269 | H8: 5399.65 | K8: 41883 | L8: 8180.2 | O8: 43191 | P8: 10759
C9: 2016 - 17 | D9: 42429 | E9: =CORREL('NSE MONEYCONTROL CORRELATION'!$K$23:$K$26,'NSE MONEYCONTROL CORRELATION'!$L$23:$L$26) -> 0.1602185601
C10: 2017 - 18 | D10: 42767 | E10: =CORREL('NSE MONEYCONTROL CORRELATION'!$K$32:$K$35,'NSE MONEYCONTROL CORRELATION'!$L$32:$L$35) -> 0.987871508 | G10: YEAR | H10: Date | K10: YEAR | L10: Date | O10: YEAR | P10: Date
C11: 2018 - 19 | D11: 43132 | E11: =CORREL('NSE MONEYCONTROL CORRELATION'!$O$5:$O$8,'NSE MONEYCONTROL CORRELATION'!$P$5:$P$8) -> -0.7600860611 | G11: 2011 - 12 | H11: 40602 | K11: 2015 - 16 | L11: 42063 | O11: 2019 - 20 | P11: 43651
C12: 2019 - 20 | D12: 43651 | E12: =CORREL('NSE MONEYCONTROL CORRELATION'!$O$14:$O$17,'NSE MONEYCONTROL CORRELATION'!$P$14:$P$17) -> -0.6363847492
C13: 2020 - 21 | D13: 43862 | E13: =CORREL('NSE MONEYCONTROL CORRELATION'!$O$23:$O$26,'NSE MONEYCONTROL CORRELATION'!$P$23:$P$26) -> -0.9407630233 | G13: Months | H13: Close | I13: Correlation | K13: Months | L13: Close | M13: Correlation | O13: Months | P13: Close | Q13: Correlation
C14: 2021 - 22 | D14: 44228 | E14: =CORREL('NSE MONEYCONTROL CORRELATION'!$O$32:$O$35,'NSE MONEYCONTROL CORRELATION'!$P$32:$P$35) -> 0.3319010984 | G14: 40544 | H14: 6181.05 | I14: =CORREL('NSE MONEYCONTROL CORRELATION'!$G$14:$G$17,'NSE MONEYCONTROL CORRELATION'!$H$14:$H$17) -> -0.24690135 | K14: 42005 | L14: 8996.6 | M14: =CORREL('NSE MONEYCONTROL CORRELATION'!$K$14:$K$17,'NSE MONEYCONTROL CORRELATION'!$L$14:$L$17) -> -0.3280414061 | O14: 43617 | P14: 12103.05 | Q14: =CORREL('NSE MONEYCONTROL CORRELATION'!$O$14:$O$17,'NSE MONEYCONTROL CORRELATION'!$P$14:$P$17) -> -0.6363847492
C15: 2022 - 23 | D15: 44593 | E15: =CORREL('NSE MONEYCONTROL CORRELATION'!$C$31:$C$34,'NSE MONEYCONTROL CORRELATION'!$D$31:$D$34) -> -0.3461117159 | G15: 40575 | H15: 5599.25 | K15: 42036 | L15: 8941.1 | O15: 43647 | P15: 11981.75
E16: =SUBTOTAL(101,'NSE MONEYCONTROL CORRELATION'!$E$3:$E$15) -> -0.1789227473 | G16: 40603 | H16: 5872 | K16: 42064 | L16: 9119.2 | O16: 43678 | P16: 11181.45
G17: 40634 | H17: 5944.45 | K17: 42095 | L17: 8844.8 | O17: 43709 | P17: 11694.85
C18: YEAR | D18: Date
G19: YEAR | H19: Date | K19: YEAR | L19: Date | O19: YEAR | P19: Date
G20: 2012 - 13 | H20: 40984 | K20: 2016 - 17 | L20: 42429 | O20: 2020 - 21 | P20: 43862
C21: Months | D21: Close | E21: Correlation
E22: =CORREL('NSE MONEYCONTROL CORRELATION'!$C$22:$C$25,'NSE MONEYCONTROL CORRELATION'!$D$22:$D$25) -> #DIV/0! | G22: Months | H22: Close | I22: Correlation | K22: Months | L22: Close | M22: Correlation | O22: Months | P22: Close | Q22: Correlation
G23: 40940 | H23: 5629.95 | I23: =CORREL('NSE MONEYCONTROL CORRELATION'!$G$23:$G$26,'NSE MONEYCONTROL CORRELATION'!$H$23:$H$26) -> -0.9977377244 | K23: 42370 | L23: 7972.55 | M23: =CORREL('NSE MONEYCONTROL CORRELATION'!$K$23:$K$26,'NSE MONEYCONTROL CORRELATION'!$L$23:$L$26) -> 0.1602185601 | O23: 43831 | P23: 12430.5 | Q23: =CORREL('NSE MONEYCONTROL CORRELATION'!$O$23:$O$26,'NSE MONEYCONTROL CORRELATION'!$P$23:$P$26) -> -0.9407630233
G24: 40969 | H24: 5499.4 | K24: 42401 | L24: 7600.45 | O24: 43862 | P24: 12246.7
G25: 41000 | H25: 5378.75 | K25: 42430 | L25: 7777.6 | O25: 43891 | P25: 11433
G26: 41030 | H26: 5279.6 | K26: 42461 | L26: 7992 | O26: 43922 | P26: 9889.05
C27: YEAR | D27: Date
C28: 2022 - 23 | D28: 44593 | G28: YEAR | H28: Date | K28: YEAR | L28: Date | O28: YEAR | P28: Date
G29: 2013 - 14 | H29: 41333 | K29: 2017 - 18 | L29: 42767 | O29: 2021 - 22 | P29: 44228
C30: Months | D30: Close | E30: Correlation
C31: 44562 | D31: 18350.95 | E31: =CORREL('NSE MONEYCONTROL CORRELATION'!$C$31:$C$34,'NSE MONEYCONTROL CORRELATION'!$D$31:$D$34) -> -0.3461117159 | G31: Months | H31: Close | I31: Correlation | K31: Months | L31: Close | M31: Correlation | O31: Months | P31: Close | Q31: Correlation
C32: 44593 | D32: 17794.6 | G32: 41275 | H32: 6111.8 | I32: =CORREL('NSE MONEYCONTROL CORRELATION'!$G$32:$G$35,'NSE MONEYCONTROL CORRELATION'!$H$32:$H$35) -> -0.9599023064 | K32: 42736 | L32: 8672.7 | M32: =CORREL('NSE MONEYCONTROL CORRELATION'!$K$32:$K$35,'NSE MONEYCONTROL CORRELATION'!$L$32:$L$35) -> 0.987871508 | O32: 44197 | P32: 14753.55 | Q32: =CORREL('NSE MONEYCONTROL CORRELATION'!$O$32:$O$35,'NSE MONEYCONTROL CORRELATION'!$P$32:$P$35) -> 0.3319010984
C33: 44621 | D33: 17559.8 | G33: 41306 | H33: 6052.95 | K33: 42767 | L33: 8982.15 | O33: 44228 | P33: 15431.75
C34: 44652 | D34: 18114.65 | G34: 41334 | H34: 5971.2 | K34: 42795 | L34: 9218.4 | O34: 44256 | P34: 15336.3
G35: 41365 | H35: 5962.3 | K35: 42826 | L35: 9367.15 | O35: 44287 | P35: 15044.35
